<?xml version="1.0"?>
<!-- This following a tutorials -->

<robot name="test_robot">

    <link name="link1"/>
    <link name="link2"/>
    <link name="link3"/>
    <link name="link4"/>

    <!-- joint for link1 to link2 and name is joint1 -->
    <!-- direction x forward to child and use ENU style -->
    <!-- Origin Tag will specify is the offset from a link -->
    <!-- axis is tag for full kinematic model. What is kinematic? 
        That is describe the motiol of points-->
    <joint name="joint1" type="continuous">
        <parent link="link1"/>
        <child link="link2"/>
        <origin xyz="5 0.6 0" rpy="0 0 0"/>
        <axis xyz="-0.707 0.707 0"/>
    </joint>

    <joint name="joint2" type="continuous">
        <parent link="link1"/>
        <child link="link3"/>
        <origin xyz="-0.4 1 0" rpy="0 0 1.57"/>
        <axis xyz="0 1 0"/>
    </joint>

    <joint name="joint3" type="continuous">
        <parent link="link3"/>
        <child link="link4"/>
        <origin xyz="1 0 0" rpy="0 0 -1.57"/>
        <axis xyz="0.707 -0.707 0"/>
    </joint>

</robot>
